Workbook

Sheet Dataset
A1: Expense Category | B1: Estimated Cost | C1: Actual Cost | D1: Payment Status | E1: Vendor | F1: Event Date | G1: Responsible Officer | H1: Budget Variance | I1: Budget Status | J1: Vendor Type (Lookup)
A2: Marketing | B2: 16503 | C2: 15232 | D2: Paid | E2: Vendor B | F2: 45705 | G2: Officer 4 | H2: =C2-B2 -> -1271 | I2: =IF(C2>B2, IF(D2="Paid", "⚠️ Over Budget", "🚨 Over Budget"), "✅ Within Budget") -> ✅ Within Budget | J2: =VLOOKUP(E2,VendorLookup!A2:B5,2,FALSE) -> Venue Provider
A3: Marketing | B3: 10166 | C3: 9436 | D3: Unpaid | E3: Vendor A | F3: 45664 | G3: Officer 2 | H3: =C3-B3 -> -730 | I3: =IF(C3>B3, IF(D3="Paid", "⚠️ Over Budget", "🚨 Over Budget"), "✅ Within Budget") -> ✅ Within Budget | J3: =VLOOKUP(E3,VendorLookup!A2:B5,2,FALSE) -> Food Services
A4: Marketing | B4: 18509 | C4: 22043 | D4: Paid | E4: Vendor C | F4: 45738 | G4: Officer 1 | H4: =C4-B4 -> 3534 | I4: =IF(C4>B4, IF(D4="Paid", "⚠️ Over Budget", "🚨 Over Budget"), "✅ Within Budget") -> ⚠️ Over Budget | J4: =VLOOKUP(E4,VendorLookup!A2:B5,2,FALSE) -> Marketing Agency
A5: Equipment | B5: 10099 | C5: 12396 | D5: Paid | E5: Vendor C | F5: 45724 | G5: Officer 3 | H5: =C5-B5 -> 2297 | I5: =IF(C5>B5, IF(D5="Paid", "⚠️ Over Budget", "🚨 Over Budget"), "✅ Within Budget") -> ⚠️ Over Budget | J5: =VLOOKUP(E5,VendorLookup!A2:B5,2,FALSE) -> Marketing Agency
A6: Logistics | B6: 13133 | C6: 13745 | D6: Paid | E6: Vendor B | F6: 45695 | G6: Officer 4 | H6: =C6-B6 -> 612 | I6: =IF(C6>B6, IF(D6="Paid", "⚠️ Over Budget", "🚨 Over Budget"), "✅ Within Budget") -> ⚠️ Over Budget | J6: =VLOOKUP(E6,VendorLookup!A2:B5,2,FALSE) -> Venue Provider
A7: Equipment | B7: 17878 | C7: 19651 | D7: Paid | E7: Vendor C | F7: 45753 | G7: Officer 4 | H7: =C7-B7 -> 1773 | I7: =IF(C7>B7, IF(D7="Paid", "⚠️ Over Budget", "🚨 Over Budget"), "✅ Within Budget") -> ⚠️ Over Budget | J7: =VLOOKUP(E7,VendorLookup!A2:B5,2,FALSE) -> Marketing Agency
A8: Equipment | B8: 12422 | C8: 9492 | D8: Paid | E8: Vendor A | F8: 45729 | G8: Officer 3 | H8: =C8-B8 -> -2930 | I8: =IF(C8>B8, IF(D8="Paid", "⚠️ Over Budget", "🚨 Over Budget"), "✅ Within Budget") -> ✅ Within Budget | J8: =VLOOKUP(E8,VendorLookup!A2:B5,2,FALSE) -> Food Services
A9: Equipment | B9: 9824 | C9: 8644 | D9: Paid | E9: Vendor D | F9: 45750 | G9: Officer 3 | H9: =C9-B9 -> -1180 | I9: =IF(C9>B9, IF(D9="Paid", "⚠️ Over Budget", "🚨 Over Budget"), "✅ Within Budget") -> ✅ Within Budget | J9: =VLOOKUP(E9,VendorLookup!A2:B5,2,FALSE) -> Equipment Supplier
A10: Marketing | B10: 8030 | C10: 11357 | D10: Unpaid | E10: Vendor B | F10: 45730 | G10: Officer 4 | H10: =C10-B10 -> 3327 | I10: =IF(C10>B10, IF(D10="Paid", "⚠️ Over Budget", "🚨 Over Budget"), "✅ Within Budget") -> 🚨 Over Budget | J10: =VLOOKUP(E10,VendorLookup!A2:B5,2,FALSE) -> Venue Provider
A11: Catering | B11: 16042 | C11: 19901 | D11: Paid | E11: Vendor D | F11: 45818 | G11: Officer 4 | H11: =C11-B11 -> 3859 | I11: =IF(C11>B11, IF(D11="Paid", "⚠️ Over Budget", "🚨 Over Budget"), "✅ Within Budget") -> ⚠️ Over Budget | J11: =VLOOKUP(E11,VendorLookup!A2:B5,2,FALSE) -> Equipment Supplier
A12: Catering | B12: 14766 | C12: 17121 | D12: Unpaid | E12: Vendor D | F12: 45723 | G12: Officer 3 | H12: =C12-B12 -> 2355 | I12: =IF(C12>B12, IF(D12="Paid", "⚠️ Over Budget", "🚨 Over Budget"), "✅ Within Budget") -> 🚨 Over Budget | J12: =VLOOKUP(E12,VendorLookup!A2:B5,2,FALSE) -> Equipment Supplier
A13: Logistics | B13: 12195 | C13: 15986 | D13: Paid | E13: Vendor C | F13: 45796 | G13: Officer 4 | H13: =C13-B13 -> 3791 | I13: =IF(C13>B13, IF(D13="Paid", "⚠️ Over Budget", "🚨 Over Budget"), "✅ Within Budget") -> ⚠️ Over Budget | J13: =VLOOKUP(E13,VendorLookup!A2:B5,2,FALSE) -> Marketing Agency
A14: Logistics | B14: 9794 | C14: 14224 | D14: Paid | E14: Vendor A | F14: 45807 | G14: Officer 4 | H14: =C14-B14 -> 4430 | I14: =IF(C14>B14, IF(D14="Paid", "⚠️ Over Budget", "🚨 Over Budget"), "✅ Within Budget") -> ⚠️ Over Budget | J14: =VLOOKUP(E14,VendorLookup!A2:B5,2,FALSE) -> Food Services
A15: Venue | B15: 8999 | C15: 6325 | D15: Paid | E15: Vendor B | F15: 45803 | G15: Officer 3 | H15: =C15-B15 -> -2674 | I15: =IF(C15>B15, IF(D15="Paid", "⚠️ Over Budget", "🚨 Over Budget"), "✅ Within Budget") -> ✅ Within Budget | J15: =VLOOKUP(E15,VendorLookup!A2:B5,2,FALSE) -> Venue Provider
A16: Catering | B16: 5073 | C16: 6871 | D16: Unpaid | E16: Vendor D | F16: 45739 | G16: Officer 4 | H16: =C16-B16 -> 1798 | I16: =IF(C16>B16, IF(D16="Paid", "⚠️ Over Budget", "🚨 Over Budget"), "✅ Within Budget") -> 🚨 Over Budget | J16: =VLOOKUP(E16,VendorLookup!A2:B5,2,FALSE) -> Equipment Supplier
A17: Equipment | B17: 8723 | C17: 8659 | D17: Paid | E17: Vendor B | F17: 45745 | G17: Officer 2 | H17: =C17-B17 -> -64 | I17: =IF(C17>B17, IF(D17="Paid", "⚠️ Over Budget", "🚨 Over Budget"), "✅ Within Budget") -> ✅ Within Budget | J17: =VLOOKUP(E17,VendorLookup!A2:B5,2,FALSE) -> Venue Provider
A18: Equipment | B18: 15320 | C18: 20268 | D18: Paid | E18: Vendor B | F18: 45679 | G18: Officer 3 | H18: =C18-B18 -> 4948 | I18: =IF(C18>B18, IF(D18="Paid", "⚠️ Over Budget", "🚨 Over Budget"), "✅ Within Budget") -> ⚠️ Over Budget | J18: =VLOOKUP(E18,VendorLookup!A2:B5,2,FALSE) -> Venue Provider
A19: Catering | B19: 10516 | C19: 13668 | D19: Unpaid | E19: Vendor C | F19: 45790 | G19: Officer 2 | H19: =C19-B19 -> 3152 | I19: =IF(C19>B19, IF(D19="Paid", "⚠️ Over Budget", "🚨 Over Budget"), "✅ Within Budget") -> 🚨 Over Budget | J19: =VLOOKUP(E19,VendorLookup!A2:B5,2,FALSE) -> Marketing Agency
A20: Equipment | B20: 16538 | C20: 15256 | D20: Unpaid | E20: Vendor A | F20: 45716 | G20: Officer 4 | H20: =C20-B20 -> -1282 | I20: =IF(C20>B20, IF(D20="Paid", "⚠️ Over Budget", "🚨 Over Budget"), "✅ Within Budget") -> ✅ Within Budget | J20: =VLOOKUP(E20,VendorLookup!A2:B5,2,FALSE) -> Food Services
A21: Catering | B21: 8798 | C21: 13303 | D21: Unpaid | E21: Vendor D | F21: 45783 | G21: Officer 1 | H21: =C21-B21 -> 4505 | I21: =IF(C21>B21, IF(D21="Paid", "⚠️ Over Budget", "🚨 Over Budget"), "✅ Within Budget") -> 🚨 Over Budget | J21: =VLOOKUP(E21,VendorLookup!A2:B5,2,FALSE) -> Equipment Supplier
A22: Venue | B22: 8258 | C22: 10098 | D22: Paid | E22: Vendor B | F22: 45658 | G22: Officer 4 | H22: =C22-B22 -> 1840 | I22: =IF(C22>B22, IF(D22="Paid", "⚠️ Over Budget", "🚨 Over Budget"), "✅ Within Budget") -> ⚠️ Over Budget | J22: =VLOOKUP(E22,VendorLookup!A2:B5,2,FALSE) -> Venue Provider
A23: Marketing | B23: 6013 | C23: 7958 | D23: Unpaid | E23: Vendor A | F23: 45780 | G23: Officer 2 | H23: =C23-B23 -> 1945 | I23: =IF(C23>B23, IF(D23="Paid", "⚠️ Over Budget", "🚨 Over Budget"), "✅ Within Budget") -> 🚨 Over Budget | J23: =VLOOKUP(E23,VendorLookup!A2:B5,2,FALSE) -> Food Services
A24: Logistics | B24: 17556 | C24: 20721 | D24: Paid | E24: Vendor C | F24: 45777 | G24: Officer 1 | H24: =C24-B24 -> 3165 | I24: =IF(C24>B24, IF(D24="Paid", "⚠️ Over Budget", "🚨 Over Budget"), "✅ Within Budget") -> ⚠️ Over Budget | J24: =VLOOKUP(E24,VendorLookup!A2:B5,2,FALSE) -> Marketing Agency
A25: Catering | B25: 14884 | C25: 17320 | D25: Unpaid | E25: Vendor D | F25: 45676 | G25: Officer 1 | H25: =C25-B25 -> 2436 | I25: =IF(C25>B25, IF(D25="Paid", "⚠️ Over Budget", "🚨 Over Budget"), "✅ Within Budget") -> 🚨 Over Budget | J25: =VLOOKUP(E25,VendorLookup!A2:B5,2,FALSE) -> Equipment Supplier
A26: Marketing | B26: 10449 | C26: 12017 | D26: Paid | E26: Vendor A | F26: 45719 | G26: Officer 2 | H26: =C26-B26 -> 1568 | I26: =IF(C26>B26, IF(D26="Paid", "⚠️ Over Budget", "🚨 Over Budget"), "✅ Within Budget") -> ⚠️ Over Budget | J26: =VLOOKUP(E26,VendorLookup!A2:B5,2,FALSE) -> Food Services
A27: Equipment | B27: 15296 | C27: 14523 | D27: Unpaid | E27: Vendor A | F27: 45660 | G27: Officer 3 | H27: =C27-B27 -> -773 | I27: =IF(C27>B27, IF(D27="Paid", "⚠️ Over Budget", "🚨 Over Budget"), "✅ Within Budget") -> ✅ Within Budget | J27: =VLOOKUP(E27,VendorLookup!A2:B5,2,FALSE) -> Food Services
A28: Venue | B28: 10905 | C28: 10957 | D28: Unpaid | E28: Vendor D | F28: 45695 | G28: Officer 4 | H28: =C28-B28 -> 52 | I28: =IF(C28>B28, IF(D28="Paid", "⚠️ Over Budget", "🚨 Over Budget"), "✅ Within Budget") -> 🚨 Over Budget | J28: =VLOOKUP(E28,VendorLookup!A2:B5,2,FALSE) -> Equipment Supplier
A29: Venue | B29: 11785 | C29: 15740 | D29: Paid | E29: Vendor D | F29: 45698 | G29: Officer 2 | H29: =C29-B29 -> 3955 | I29: =IF(C29>B29, IF(D29="Paid", "⚠️ Over Budget", "🚨 Over Budget"), "✅ Within Budget") -> ⚠️ Over Budget | J29: =VLOOKUP(E29,VendorLookup!A2:B5,2,FALSE) -> Equipment Supplier
A30: Equipment | B30: 17927 | C30: 15130 | D30: Paid | E30: Vendor B | F30: 45796 | G30: Officer 2 | H30: =C30-B30 -> -2797 | I30: =IF(C30>B30, IF(D30="Paid", "⚠️ Over Budget", "🚨 Over Budget"), "✅ Within Budget") -> ✅ Within Budget | J30: =VLOOKUP(E30,VendorLookup!A2:B5,2,FALSE) -> Venue Provider
A31: Equipment | B31: 5198 | C31: 8704 | D31: Paid | E31: Vendor D | F31: 45785 | G31: Officer 1 | H31: =C31-B31 -> 3506 | I31: =IF(C31>B31, IF(D31="Paid", "⚠️ Over Budget", "🚨 Over Budget"), "✅ Within Budget") -> ⚠️ Over Budget | J31: =VLOOKUP(E31,VendorLookup!A2:B5,2,FALSE) -> Equipment Supplier
A32: Logistics | B32: 16006 | C32: 20884 | D32: Unpaid | E32: Vendor D | F32: 45802 | G32: Officer 4 | H32: =C32-B32 -> 4878 | I32: =IF(C32>B32, IF(D32="Paid", "⚠️ Over Budget", "🚨 Over Budget"), "✅ Within Budget") -> 🚨 Over Budget | J32: =VLOOKUP(E32,VendorLookup!A2:B5,2,FALSE) -> Equipment Supplier
A33: Marketing | B33: 8519 | C33: 7972 | D33: Paid | E33: Vendor D | F33: 45664 | G33: Officer 2 | H33: =C33-B33 -> -547 | I33: =IF(C33>B33, IF(D33="Paid", "⚠️ Over Budget", "🚨 Over Budget"), "✅ Within Budget") -> ✅ Within Budget | J33: =VLOOKUP(E33,VendorLookup!A2:B5,2,FALSE) -> Equipment Supplier
A34: Logistics | B34: 12785 | C34: 17387 | D34: Unpaid | E34: Vendor D | F34: 45723 | G34: Officer 1 | H34: =C34-B34 -> 4602 | I34: =IF(C34>B34, IF(D34="Paid", "⚠️ Over Budget", "🚨 Over Budget"), "✅ Within Budget") -> 🚨 Over Budget | J34: =VLOOKUP(E34,VendorLookup!A2:B5,2,FALSE) -> Equipment Supplier
A35: Logistics | B35: 16586 | C35: 19015 | D35: Paid | E35: Vendor B | F35: 45741 | G35: Officer 4 | H35: =C35-B35 -> 2429 | I35: =IF(C35>B35, IF(D35="Paid", "⚠️ Over Budget", "🚨 Over Budget"), "✅ Within Budget") -> ⚠️ Over Budget | J35: =VLOOKUP(E35,VendorLookup!A2:B5,2,FALSE) -> Venue Provider
A36: Equipment | B36: 19743 | C36: 22924 | D36: Paid | E36: Vendor C | F36: 45696 | G36: Officer 3 | H36: =C36-B36 -> 3181 | I36: =IF(C36>B36, IF(D36="Paid", "⚠️ Over Budget", "🚨 Over Budget"), "✅ Within Budget") -> ⚠️ Over Budget | J36: =VLOOKUP(E36,VendorLookup!A2:B5,2,FALSE) -> Marketing Agency
A37: Catering | B37: 19481 | C37: 23881 | D37: Unpaid | E37: Vendor A | F37: 45712 | G37: Officer 3 | H37: =C37-B37 -> 4400 | I37: =IF(C37>B37, IF(D37="Paid", "⚠️ Over Budget", "🚨 Over Budget"), "✅ Within Budget") -> 🚨 Over Budget | J37: =VLOOKUP(E37,VendorLookup!A2:B5,2,FALSE) -> Food Services
A38: Venue | B38: 16030 | C38: 13380 | D38: Paid | E38: Vendor B | F38: 45713 | G38: Officer 3 | H38: =C38-B38 -> -2650 | I38: =IF(C38>B38, IF(D38="Paid", "⚠️ Over Budget", "🚨 Over Budget"), "✅ Within Budget") -> ✅ Within Budget | J38: =VLOOKUP(E38,VendorLookup!A2:B5,2,FALSE) -> Venue Provider
A39: Equipment | B39: 15935 | C39: 16175 | D39: Paid | E39: Vendor C | F39: 45664 | G39: Officer 3 | H39: =C39-B39 -> 240 | I39: =IF(C39>B39, IF(D39="Paid", "⚠️ Over Budget", "🚨 Over Budget"), "✅ Within Budget") -> ⚠️ Over Budget | J39: =VLOOKUP(E39,VendorLookup!A2:B5,2,FALSE) -> Marketing Agency
A40: Marketing | B40: 7393 | C40: 5656 | D40: Paid | E40: Vendor C | F40: 45666 | G40: Officer 3 | H40: =C40-B40 -> -1737 | I40: =IF(C40>B40, IF(D40="Paid", "⚠️ Over Budget", "🚨 Over Budget"), "✅ Within Budget") -> ✅ Within Budget | J40: =VLOOKUP(E40,VendorLookup!A2:B5,2,FALSE) -> Marketing Agency
...

Sheet VendorLookup
A1: Vendor | B1: Vendor Type
A2: Vendor A | B2: Food Services
A3: Vendor B | B3: Venue Provider
A4: Vendor C | B4: Marketing Agency
A5: Vendor D | B5: Equipment Supplier

Sheet Analytics Summary
A1: PIVOT TABLE 1: Total Actual Cost per Expense Category
A3: Expense Category | B3: Total Actual Cost | D3: Total Estimated (SUM) | E3: =SUM(Dataset!B2:B61) -> 721075
A4: Catering | B4: =SUMIF(Dataset!A2:A61,"Catering",Dataset!C2:C61) -> 162835 | D4: Average Actual (AVERAGE) | E4: =AVERAGE(Dataset!C2:C61) -> 13521.717
A5: Venue | B5: =SUMIF(Dataset!A2:A61,"Venue",Dataset!C2:C61) -> 141268 | D5: Unpaid Count (COUNTIF) | E5: =COUNTIF(Dataset!D2:D61,"Unpaid") -> 28
A6: Marketing | B6: =SUMIF(Dataset!A2:A61,"Marketing",Dataset!C2:C61) -> 146899 | D6: Total Catering (SUMIF) | E6: =SUMIF(Dataset!A2:A61,"Catering",Dataset!C2:C61) -> 162835
A7: Equipment | B7: =SUMIF(Dataset!A2:A61,"Equipment",Dataset!C2:C61) -> 187964
A8: Logistics | B8: =SUMIF(Dataset!A2:A61,"Logistics",Dataset!C2:C61) -> 172337
A10: PIVOT TABLE 2: Total Actual Cost per Responsible Officer
A12: Responsible Officer | B12: Total Actual Cost
A13: Officer 1 | B13: =SUMIF(Dataset!G2:G61,"Officer 1",Dataset!C2:C61) -> 159112
A14: Officer 2 | B14: =SUMIF(Dataset!G2:G61,"Officer 2",Dataset!C2:C61) -> 156110
A15: Officer 3 | B15: =SUMIF(Dataset!G2:G61,"Officer 3",Dataset!C2:C61) -> 242716
A16: Officer 4 | B16: =SUMIF(Dataset!G2:G61,"Officer 4",Dataset!C2:C61) -> 253365

Sheet Dashboard
A1: Total Estimated | B1: =SUM(Dataset!B2:B61) -> 721075
A2: Total Actual | B2: =SUM(Dataset!C2:C61) -> 811303
A3: Highest Actual | B3: =MAX(Dataset!C2:C61) -> 23881
A4: Lowest Actual | B4: =MIN(Dataset!C2:C61) -> 2991
A6: Paid | B6: =COUNTIF(Dataset!D2:D61,"Paid") -> 32
A7: Unpaid | B7: =COUNTIF(Dataset!D2:D61,"Unpaid") -> 28
A10: Month | B10: Total Spending
A11: Jan | B11: 95598
A12: Feb | B12: 96967
A13: Mar | B13: 49488
A14: Apr | B14: 75914
A15: May | B15: 76788
A16: Jun | B16: 37476

Sheet Refelctions
A1: 1. Mico Grande – Project Manager As the Project Manager, I was responsible for organizing the overall structure of the spreadsheet and ensuring that all sheets were logically connected. I coordinated task assignments, reviewed formulas and summaries, and made sure deadlines were followed. One challenge I faced was keeping everything consistent while different members worked on separate parts. Through this project, I developed stronger leadership and project coordination skills, especially in managing collaboration within Google Sheets. 2. Aaron Jan Rafael Malda – Data Entry & Cleaning As the Data Entry & Cleaning specialist, I designed the dataset structure with more than eight columns and encoded the initial raw data. I ensured the data was clean, properly formatted, and realistic based on the scenario. A challenge I encountered was maintaining consistency in formatting and avoiding duplicate or incorrect entries. I learned how important data validation and organization are in building reliable spreadsheets. 3. Dan Gabriel Jaraplasan – Formula & Logic Specialist As the Formula & Logic Specialist, I implemented key formulas such as SUM, AVERAGE, VLOOKUP, and nested IF statements. My role was to ensure that calculations were accurate and that automated logic worked correctly across sheets. One challenge was troubleshooting errors caused by incorrect references or syntax issues. I improved my understanding of advanced spreadsheet functions and logical structuring. 4. Gaius Vincent Delos Reyes – Pivot & Analysis Specialist As the Pivot & Analysis Specialist, I created the Analytics Summary sheet and built pivot tables to summarize the dataset. I analyzed totals per category and officer to provide meaningful insights. A challenge I faced was ensuring the pivot tables updated correctly with the dataset. I learned how to transform raw data into summarized insights for decision-making. 5. Jama Paolo Sariol – Dashboard Designer As the Dashboard Designer, I developed the visual layout and core charts for the Dashboard sheet. I ensured that the charts were clear, readable, and visually aligned with the summary metrics. One challenge was selecting the appropriate chart types to best represent the data. I learned how data visualization improves understanding and presentation quality. 6. Jay Fuentes – Quality Assurance (QA) As the Quality Assurance member, I reviewed formulas, checked for errors, and ensured consistency across all sheets. I carefully examined calculations, formatting, and summary outputs to prevent mistakes. One challenge was identifying hidden formula errors that did not immediately show obvious issues. I strengthened my attention to detail and error-checking skills. 7. Marc Reil Bujawwe – Assistant Data Specialist As the Assistant Data Specialist, I helped generate 60 rows of realistic event data for the dataset. I ensured that the entries matched the project scenario and maintained logical consistency. A challenge I faced was balancing realism with variation in the data. I learned how structured datasets improve analysis and reporting accuracy. 8. Prince Audi Baldonado – Assistant Formula Tech As the Assistant Formula Tech, I supported the implementation of complex formulas and verified that no error flags appeared in the sheet. I assisted in debugging nested IF statements and lookup functions. A challenge was understanding how different formulas interacted with each other. I gained deeper knowledge in troubleshooting spreadsheet logic. 9. Yuri Banaag – Assistant Visual Designer As the Assistant Visual Designer, I helped refine the dashboard’s formatting, color palette, and visual presentation. I ensured charts were labeled properly and aligned with summary metrics. One challenge was maintaining visual consistency while keeping the dashboard professional. I learned how design principles enhance clarity in data reporting.
